[2023-03-10T22:31:18.347+0000] {taskinstance.py:1083} INFO - Dependencies all met for <TaskInstance: projeto_agro.extract_data manual__2023-03-10T22:31:09.116777+00:00 [queued]>
[2023-03-10T22:31:18.358+0000] {taskinstance.py:1083} INFO - Dependencies all met for <TaskInstance: projeto_agro.extract_data manual__2023-03-10T22:31:09.116777+00:00 [queued]>
[2023-03-10T22:31:18.359+0000] {taskinstance.py:1279} INFO - 
--------------------------------------------------------------------------------
[2023-03-10T22:31:18.359+0000] {taskinstance.py:1280} INFO - Starting attempt 1 of 1
[2023-03-10T22:31:18.359+0000] {taskinstance.py:1281} INFO - 
--------------------------------------------------------------------------------
[2023-03-10T22:31:18.373+0000] {taskinstance.py:1300} INFO - Executing <Task(PythonOperator): extract_data> on 2023-03-10 22:31:09.116777+00:00
[2023-03-10T22:31:18.376+0000] {standard_task_runner.py:55} INFO - Started process 124 to run task
[2023-03-10T22:31:18.379+0000] {standard_task_runner.py:82} INFO - Running: ['airflow', 'tasks', 'run', 'projeto_agro', 'extract_data', 'manual__2023-03-10T22:31:09.116777+00:00', '--job-id', '16', '--raw', '--subdir', 'DAGS_FOLDER/main.py', '--cfg-path', '/tmp/tmp31z2wa7l']
[2023-03-10T22:31:18.380+0000] {standard_task_runner.py:83} INFO - Job 16: Subtask extract_data
[2023-03-10T22:31:18.439+0000] {task_command.py:388} INFO - Running <TaskInstance: projeto_agro.extract_data manual__2023-03-10T22:31:09.116777+00:00 [running]> on host 1b87c3940542
[2023-03-10T22:31:18.504+0000] {taskinstance.py:1507} INFO - Exporting the following env vars:
AIRFLOW_CTX_DAG_OWNER=airflow
AIRFLOW_CTX_DAG_ID=projeto_agro
AIRFLOW_CTX_TASK_ID=extract_data
AIRFLOW_CTX_EXECUTION_DATE=2023-03-10T22:31:09.116777+00:00
AIRFLOW_CTX_TRY_NUMBER=1
AIRFLOW_CTX_DAG_RUN_ID=manual__2023-03-10T22:31:09.116777+00:00
[2023-03-10T22:31:19.618+0000] {taskinstance.py:1768} ERROR - Task failed with exception
Traceback (most recent call last):
  File "/usr/local/lib/python3.9/site-packages/airflow/operators/python.py", line 175, in execute
    return_value = self.execute_callable()
  File "/usr/local/lib/python3.9/site-packages/airflow/operators/python.py", line 192, in execute_callable
    return self.python_callable(*self.op_args, **self.op_kwargs)
  File "/opt/airflow/dags/main.py", line 15, in extract
    extract = Extract()
  File "/opt/airflow/dags/../../scripts/extract.py", line 9, in __init__
    self._get_faostat_data()
  File "/opt/airflow/dags/../../scripts/extract.py", line 15, in _get_faostat_data
    self.dataset_flags = pd.read_csv(zip_file.open('Production_Crops_Livestock_E_Flags.csv'))
NameError: name 'pd' is not defined
[2023-03-10T22:31:19.633+0000] {taskinstance.py:1318} INFO - Marking task as FAILED. dag_id=projeto_agro, task_id=extract_data, execution_date=20230310T223109, start_date=20230310T223118, end_date=20230310T223119
[2023-03-10T22:31:19.644+0000] {standard_task_runner.py:100} ERROR - Failed to execute job 16 for task extract_data (name 'pd' is not defined; 124)
[2023-03-10T22:31:19.674+0000] {local_task_job.py:208} INFO - Task exited with return code 1
[2023-03-10T22:31:19.691+0000] {taskinstance.py:2578} INFO - 0 downstream tasks scheduled from follow-on schedule check
