[2023-03-27T20:41:34.092+0000] {taskinstance.py:1087} INFO - Dependencies all met for <TaskInstance: projeto_agro.extract_data manual__2023-03-27T20:41:30.170389+00:00 [queued]>
[2023-03-27T20:41:34.105+0000] {taskinstance.py:1087} INFO - Dependencies all met for <TaskInstance: projeto_agro.extract_data manual__2023-03-27T20:41:30.170389+00:00 [queued]>
[2023-03-27T20:41:34.105+0000] {taskinstance.py:1283} INFO - 
--------------------------------------------------------------------------------
[2023-03-27T20:41:34.105+0000] {taskinstance.py:1284} INFO - Starting attempt 1 of 1
[2023-03-27T20:41:34.105+0000] {taskinstance.py:1285} INFO - 
--------------------------------------------------------------------------------
[2023-03-27T20:41:34.121+0000] {taskinstance.py:1304} INFO - Executing <Task(PythonOperator): extract_data> on 2023-03-27 20:41:30.170389+00:00
[2023-03-27T20:41:34.126+0000] {standard_task_runner.py:55} INFO - Started process 83 to run task
[2023-03-27T20:41:34.129+0000] {standard_task_runner.py:82} INFO - Running: ['airflow', 'tasks', 'run', 'projeto_agro', 'extract_data', 'manual__2023-03-27T20:41:30.170389+00:00', '--job-id', '137', '--raw', '--subdir', 'DAGS_FOLDER/main.py', '--cfg-path', '/tmp/tmp3m4nisr7']
[2023-03-27T20:41:34.132+0000] {standard_task_runner.py:83} INFO - Job 137: Subtask extract_data
[2023-03-27T20:41:34.234+0000] {task_command.py:389} INFO - Running <TaskInstance: projeto_agro.extract_data manual__2023-03-27T20:41:30.170389+00:00 [running]> on host 48ec747c45e3
[2023-03-27T20:41:34.328+0000] {taskinstance.py:1511} INFO - Exporting the following env vars:
AIRFLOW_CTX_DAG_OWNER=airflow
AIRFLOW_CTX_DAG_ID=projeto_agro
AIRFLOW_CTX_TASK_ID=extract_data
AIRFLOW_CTX_EXECUTION_DATE=2023-03-27T20:41:30.170389+00:00
AIRFLOW_CTX_TRY_NUMBER=1
AIRFLOW_CTX_DAG_RUN_ID=manual__2023-03-27T20:41:30.170389+00:00
[2023-03-27T20:41:49.767+0000] {logging_mixin.py:137} WARNING - /opt/airflow/dags/../../scripts/extract.py:31 DtypeWarning: Columns (2) have mixed types. Specify dtype option on import or set low_memory=False.
[2023-03-27T20:41:59.003+0000] {taskinstance.py:1772} ERROR - Task failed with exception
Traceback (most recent call last):
  File "/usr/local/lib/python3.9/site-packages/airflow/operators/python.py", line 175, in execute
    return_value = self.execute_callable()
  File "/usr/local/lib/python3.9/site-packages/airflow/operators/python.py", line 192, in execute_callable
    return self.python_callable(*self.op_args, **self.op_kwargs)
  File "/opt/airflow/dags/main.py", line 17, in extract
    dict_files_name=extract.save_data_raw()
  File "/opt/airflow/dags/../../scripts/extract.py", line 55, in save_data_raw
    self.all_data_faostat.to_parquet(f'/opt/data/data_raw/'+dict_files_name['path_file_faostat'])
  File "/usr/local/lib/python3.9/site-packages/pandas/util/_decorators.py", line 211, in wrapper
    return func(*args, **kwargs)
  File "/usr/local/lib/python3.9/site-packages/pandas/core/frame.py", line 2975, in to_parquet
    return to_parquet(
  File "/usr/local/lib/python3.9/site-packages/pandas/io/parquet.py", line 430, in to_parquet
    impl.write(
  File "/usr/local/lib/python3.9/site-packages/pandas/io/parquet.py", line 176, in write
    path_or_handle, handles, kwargs["filesystem"] = _get_path_or_handle(
  File "/usr/local/lib/python3.9/site-packages/pandas/io/parquet.py", line 102, in _get_path_or_handle
    handles = get_handle(
  File "/usr/local/lib/python3.9/site-packages/pandas/io/common.py", line 734, in get_handle
    check_parent_directory(str(handle))
  File "/usr/local/lib/python3.9/site-packages/pandas/io/common.py", line 597, in check_parent_directory
    raise OSError(rf"Cannot save file into a non-existent directory: '{parent}'")
OSError: Cannot save file into a non-existent directory: '/opt/data/data_raw/03-27-2023'
[2023-03-27T20:41:59.021+0000] {taskinstance.py:1322} INFO - Marking task as FAILED. dag_id=projeto_agro, task_id=extract_data, execution_date=20230327T204130, start_date=20230327T204134, end_date=20230327T204159
[2023-03-27T20:41:59.032+0000] {standard_task_runner.py:100} ERROR - Failed to execute job 137 for task extract_data (Cannot save file into a non-existent directory: '/opt/data/data_raw/03-27-2023'; 83)
[2023-03-27T20:41:59.084+0000] {local_task_job.py:159} INFO - Task exited with return code 1
[2023-03-27T20:41:59.110+0000] {taskinstance.py:2582} INFO - 0 downstream tasks scheduled from follow-on schedule check
