[2023-03-28T00:34:16.910+0000] {taskinstance.py:1087} INFO - Dependencies all met for <TaskInstance: projeto_agro.transform_data manual__2023-03-28T00:33:03.615873+00:00 [queued]>
[2023-03-28T00:34:16.922+0000] {taskinstance.py:1087} INFO - Dependencies all met for <TaskInstance: projeto_agro.transform_data manual__2023-03-28T00:33:03.615873+00:00 [queued]>
[2023-03-28T00:34:16.922+0000] {taskinstance.py:1283} INFO - 
--------------------------------------------------------------------------------
[2023-03-28T00:34:16.922+0000] {taskinstance.py:1284} INFO - Starting attempt 1 of 1
[2023-03-28T00:34:16.923+0000] {taskinstance.py:1285} INFO - 
--------------------------------------------------------------------------------
[2023-03-28T00:34:16.939+0000] {taskinstance.py:1304} INFO - Executing <Task(PythonOperator): transform_data> on 2023-03-28 00:33:03.615873+00:00
[2023-03-28T00:34:16.944+0000] {standard_task_runner.py:55} INFO - Started process 1443 to run task
[2023-03-28T00:34:16.946+0000] {standard_task_runner.py:82} INFO - Running: ['airflow', 'tasks', 'run', 'projeto_agro', 'transform_data', 'manual__2023-03-28T00:33:03.615873+00:00', '--job-id', '158', '--raw', '--subdir', 'DAGS_FOLDER/main.py', '--cfg-path', '/tmp/tmp70yvmiub']
[2023-03-28T00:34:16.948+0000] {standard_task_runner.py:83} INFO - Job 158: Subtask transform_data
[2023-03-28T00:34:17.022+0000] {task_command.py:389} INFO - Running <TaskInstance: projeto_agro.transform_data manual__2023-03-28T00:33:03.615873+00:00 [running]> on host 48ec747c45e3
[2023-03-28T00:34:17.105+0000] {taskinstance.py:1511} INFO - Exporting the following env vars:
AIRFLOW_CTX_DAG_OWNER=airflow
AIRFLOW_CTX_DAG_ID=projeto_agro
AIRFLOW_CTX_TASK_ID=transform_data
AIRFLOW_CTX_EXECUTION_DATE=2023-03-28T00:33:03.615873+00:00
AIRFLOW_CTX_TRY_NUMBER=1
AIRFLOW_CTX_DAG_RUN_ID=manual__2023-03-28T00:33:03.615873+00:00
[2023-03-28T00:35:16.349+0000] {taskinstance.py:1772} ERROR - Task failed with exception
Traceback (most recent call last):
  File "/usr/local/lib/python3.9/site-packages/airflow/operators/python.py", line 175, in execute
    return_value = self.execute_callable()
  File "/usr/local/lib/python3.9/site-packages/airflow/operators/python.py", line 192, in execute_callable
    return self.python_callable(*self.op_args, **self.op_kwargs)
  File "/opt/airflow/dags/main.py", line 31, in transform
    transform.clean_dataset()
  File "/opt/airflow/dags/../../scripts/transform.py", line 94, in clean_dataset
    self.infos_countries = self.infos_countries[infos_countries['LocTypeID'] == 4]
NameError: name 'infos_countries' is not defined
[2023-03-28T00:35:16.518+0000] {taskinstance.py:1322} INFO - Marking task as FAILED. dag_id=projeto_agro, task_id=transform_data, execution_date=20230328T003303, start_date=20230328T003416, end_date=20230328T003516
[2023-03-28T00:35:16.640+0000] {standard_task_runner.py:100} ERROR - Failed to execute job 158 for task transform_data (name 'infos_countries' is not defined; 1443)
[2023-03-28T00:35:16.960+0000] {local_task_job.py:159} INFO - Task exited with return code 1
[2023-03-28T00:35:17.051+0000] {taskinstance.py:2582} INFO - 0 downstream tasks scheduled from follow-on schedule check
