[2023-03-28T00:01:08.991+0000] {taskinstance.py:1087} INFO - Dependencies all met for <TaskInstance: projeto_agro.transform_data scheduled__2023-03-27T00:00:00+00:00 [queued]>
[2023-03-28T00:01:09.001+0000] {taskinstance.py:1087} INFO - Dependencies all met for <TaskInstance: projeto_agro.transform_data scheduled__2023-03-27T00:00:00+00:00 [queued]>
[2023-03-28T00:01:09.001+0000] {taskinstance.py:1283} INFO - 
--------------------------------------------------------------------------------
[2023-03-28T00:01:09.001+0000] {taskinstance.py:1284} INFO - Starting attempt 1 of 1
[2023-03-28T00:01:09.001+0000] {taskinstance.py:1285} INFO - 
--------------------------------------------------------------------------------
[2023-03-28T00:01:09.015+0000] {taskinstance.py:1304} INFO - Executing <Task(PythonOperator): transform_data> on 2023-03-27 00:00:00+00:00
[2023-03-28T00:01:09.020+0000] {standard_task_runner.py:55} INFO - Started process 1176 to run task
[2023-03-28T00:01:09.022+0000] {standard_task_runner.py:82} INFO - Running: ['airflow', 'tasks', 'run', 'projeto_agro', 'transform_data', 'scheduled__2023-03-27T00:00:00+00:00', '--job-id', '152', '--raw', '--subdir', 'DAGS_FOLDER/main.py', '--cfg-path', '/tmp/tmprzft2wlo']
[2023-03-28T00:01:09.024+0000] {standard_task_runner.py:83} INFO - Job 152: Subtask transform_data
[2023-03-28T00:01:09.087+0000] {task_command.py:389} INFO - Running <TaskInstance: projeto_agro.transform_data scheduled__2023-03-27T00:00:00+00:00 [running]> on host 48ec747c45e3
[2023-03-28T00:01:09.156+0000] {taskinstance.py:1511} INFO - Exporting the following env vars:
AIRFLOW_CTX_DAG_OWNER=airflow
AIRFLOW_CTX_DAG_ID=projeto_agro
AIRFLOW_CTX_TASK_ID=transform_data
AIRFLOW_CTX_EXECUTION_DATE=2023-03-27T00:00:00+00:00
AIRFLOW_CTX_TRY_NUMBER=1
AIRFLOW_CTX_DAG_RUN_ID=scheduled__2023-03-27T00:00:00+00:00
[2023-03-28T00:01:25.274+0000] {logging_mixin.py:137} INFO -      Item Code   CPC Code                                               Item
0          101     '01195                                        Canary seed
1         1016     '02123                                              Goats
2         1017     '21116                     Meat of goat; fresh or chilled
3         1018     '21156     Edible offal of goat; fresh; chilled or frozen
4         1019     '21515                               Goat fat; unrendered
..         ...        ...                                                ...
302        982     '02291                                  Raw milk of sheep
303        983  '22249.01                      Butter and ghee of sheep milk
304        984     '22253      Cheese from milk of sheep; fresh or processed
305        987     '02941  Shorn wool; greasy; including fleece-washed sh...
306        995     '02953              Raw hides and skins of sheep or lambs

[307 rows x 3 columns]
[2023-03-28T00:01:37.588+0000] {taskinstance.py:1772} ERROR - Task failed with exception
Traceback (most recent call last):
  File "/usr/local/lib/python3.9/site-packages/airflow/operators/python.py", line 175, in execute
    return_value = self.execute_callable()
  File "/usr/local/lib/python3.9/site-packages/airflow/operators/python.py", line 192, in execute_callable
    return self.python_callable(*self.op_args, **self.op_kwargs)
  File "/opt/airflow/dags/main.py", line 30, in transform
    transform.transform_columns()
  File "/opt/airflow/dags/../../scripts/transform.py", line 63, in transform_columns
    self.dataframe_years_flag = self.dataframe_years_flag.melt(id_vars=['Area Code (M49)', 'Item Code', 'Element Code', 'id'],
  File "/usr/local/lib/python3.9/site-packages/pandas/core/frame.py", line 9124, in melt
    return melt(
  File "/usr/local/lib/python3.9/site-packages/pandas/core/reshape/melt.py", line 77, in melt
    raise KeyError(
KeyError: "The following 'id_vars' are not present in the DataFrame: ['id']"
[2023-03-28T00:01:37.750+0000] {taskinstance.py:1322} INFO - Marking task as FAILED. dag_id=projeto_agro, task_id=transform_data, execution_date=20230327T000000, start_date=20230328T000108, end_date=20230328T000137
[2023-03-28T00:01:37.849+0000] {standard_task_runner.py:100} ERROR - Failed to execute job 152 for task transform_data ("The following 'id_vars' are not present in the DataFrame: ['id']"; 1176)
[2023-03-28T00:01:38.067+0000] {local_task_job.py:159} INFO - Task exited with return code 1
[2023-03-28T00:01:38.154+0000] {taskinstance.py:2582} INFO - 0 downstream tasks scheduled from follow-on schedule check
