[2023-03-27T03:16:41.162+0000] {taskinstance.py:1087} INFO - Dependencies all met for <TaskInstance: projeto_agro.extract_data manual__2023-03-27T03:16:38.211447+00:00 [queued]>
[2023-03-27T03:16:41.171+0000] {taskinstance.py:1087} INFO - Dependencies all met for <TaskInstance: projeto_agro.extract_data manual__2023-03-27T03:16:38.211447+00:00 [queued]>
[2023-03-27T03:16:41.172+0000] {taskinstance.py:1283} INFO - 
--------------------------------------------------------------------------------
[2023-03-27T03:16:41.172+0000] {taskinstance.py:1284} INFO - Starting attempt 1 of 1
[2023-03-27T03:16:41.172+0000] {taskinstance.py:1285} INFO - 
--------------------------------------------------------------------------------
[2023-03-27T03:16:41.185+0000] {taskinstance.py:1304} INFO - Executing <Task(PythonOperator): extract_data> on 2023-03-27 03:16:38.211447+00:00
[2023-03-27T03:16:41.190+0000] {standard_task_runner.py:55} INFO - Started process 235 to run task
[2023-03-27T03:16:41.192+0000] {standard_task_runner.py:82} INFO - Running: ['airflow', 'tasks', 'run', 'projeto_agro', 'extract_data', 'manual__2023-03-27T03:16:38.211447+00:00', '--job-id', '91', '--raw', '--subdir', 'DAGS_FOLDER/main.py', '--cfg-path', '/tmp/tmpfw0u9ljh']
[2023-03-27T03:16:41.193+0000] {standard_task_runner.py:83} INFO - Job 91: Subtask extract_data
[2023-03-27T03:16:41.263+0000] {task_command.py:389} INFO - Running <TaskInstance: projeto_agro.extract_data manual__2023-03-27T03:16:38.211447+00:00 [running]> on host 264f1e537a4a
[2023-03-27T03:16:41.413+0000] {taskinstance.py:1511} INFO - Exporting the following env vars:
AIRFLOW_CTX_DAG_OWNER=airflow
AIRFLOW_CTX_DAG_ID=projeto_agro
AIRFLOW_CTX_TASK_ID=extract_data
AIRFLOW_CTX_EXECUTION_DATE=2023-03-27T03:16:38.211447+00:00
AIRFLOW_CTX_TRY_NUMBER=1
AIRFLOW_CTX_DAG_RUN_ID=manual__2023-03-27T03:16:38.211447+00:00
[2023-03-27T03:16:55.970+0000] {logging_mixin.py:137} WARNING - /opt/airflow/dags/../../scripts/extract.py:27 DtypeWarning: Columns (2) have mixed types. Specify dtype option on import or set low_memory=False.
[2023-03-27T03:16:59.216+0000] {_metadata.py:99} WARNING - Compute Engine Metadata server unavailable on attempt 1 of 3. Reason: timed out
[2023-03-27T03:16:59.288+0000] {_metadata.py:99} WARNING - Compute Engine Metadata server unavailable on attempt 2 of 3. Reason: [Errno 113] No route to host
[2023-03-27T03:17:02.292+0000] {_metadata.py:99} WARNING - Compute Engine Metadata server unavailable on attempt 3 of 3. Reason: timed out
[2023-03-27T03:17:02.292+0000] {_default.py:296} WARNING - Authentication failed using Compute Engine authentication due to unavailable metadata server.
[2023-03-27T03:17:02.424+0000] {_metadata.py:154} WARNING - Compute Engine Metadata server unavailable on attempt 1 of 5. Reason: HTTPConnectionPool(host='metadata.google.internal', port=80): Max retries exceeded with url: /computeMetadata/v1/instance/service-accounts/default/?recursive=true (Caused by NewConnectionError('<urllib3.connection.HTTPConnection object at 0x7f86be5f7760>: Failed to establish a new connection: [Errno -2] Name or service not known'))
[2023-03-27T03:17:02.617+0000] {_metadata.py:154} WARNING - Compute Engine Metadata server unavailable on attempt 2 of 5. Reason: HTTPConnectionPool(host='metadata.google.internal', port=80): Max retries exceeded with url: /computeMetadata/v1/instance/service-accounts/default/?recursive=true (Caused by NewConnectionError('<urllib3.connection.HTTPConnection object at 0x7f86be5f7ac0>: Failed to establish a new connection: [Errno -2] Name or service not known'))
[2023-03-27T03:17:02.719+0000] {_metadata.py:154} WARNING - Compute Engine Metadata server unavailable on attempt 3 of 5. Reason: HTTPConnectionPool(host='metadata.google.internal', port=80): Max retries exceeded with url: /computeMetadata/v1/instance/service-accounts/default/?recursive=true (Caused by NewConnectionError('<urllib3.connection.HTTPConnection object at 0x7f86be611070>: Failed to establish a new connection: [Errno -2] Name or service not known'))
[2023-03-27T03:17:02.834+0000] {_metadata.py:154} WARNING - Compute Engine Metadata server unavailable on attempt 4 of 5. Reason: HTTPConnectionPool(host='metadata.google.internal', port=80): Max retries exceeded with url: /computeMetadata/v1/instance/service-accounts/default/?recursive=true (Caused by NewConnectionError('<urllib3.connection.HTTPConnection object at 0x7f86be611400>: Failed to establish a new connection: [Errno -2] Name or service not known'))
[2023-03-27T03:17:03.026+0000] {_metadata.py:154} WARNING - Compute Engine Metadata server unavailable on attempt 5 of 5. Reason: HTTPConnectionPool(host='metadata.google.internal', port=80): Max retries exceeded with url: /computeMetadata/v1/instance/service-accounts/default/?recursive=true (Caused by NewConnectionError('<urllib3.connection.HTTPConnection object at 0x7f86be611880>: Failed to establish a new connection: [Errno -2] Name or service not known'))
[2023-03-27T03:17:04.153+0000] {retry.py:148} ERROR - _request non-retriable exception: Anonymous caller does not have storage.objects.create access to the Google Cloud Storage object. Permission 'storage.objects.create' denied on resource (or it may not exist)., 401
Traceback (most recent call last):
  File "/usr/local/lib/python3.9/site-packages/gcsfs/retry.py", line 114, in retry_request
    return await func(*args, **kwargs)
  File "/usr/local/lib/python3.9/site-packages/gcsfs/core.py", line 411, in _request
    validate_response(status, contents, path, args)
  File "/usr/local/lib/python3.9/site-packages/gcsfs/retry.py", line 101, in validate_response
    raise HttpError(error)
gcsfs.retry.HttpError: Anonymous caller does not have storage.objects.create access to the Google Cloud Storage object. Permission 'storage.objects.create' denied on resource (or it may not exist)., 401
[2023-03-27T03:17:04.156+0000] {taskinstance.py:1772} ERROR - Task failed with exception
Traceback (most recent call last):
  File "/usr/local/lib/python3.9/site-packages/airflow/operators/python.py", line 175, in execute
    return_value = self.execute_callable()
  File "/usr/local/lib/python3.9/site-packages/airflow/operators/python.py", line 192, in execute_callable
    return self.python_callable(*self.op_args, **self.op_kwargs)
  File "/opt/airflow/dags/main.py", line 16, in extract
    extract.save_data_raw()
  File "/opt/airflow/dags/../../scripts/extract.py", line 36, in save_data_raw
    self.all_data_faostat.to_csv('gs://data_raw_area_project_agro/' + path_file_faostat)
  File "/usr/local/lib/python3.9/site-packages/pandas/util/_decorators.py", line 211, in wrapper
    return func(*args, **kwargs)
  File "/usr/local/lib/python3.9/site-packages/pandas/core/generic.py", line 3720, in to_csv
    return DataFrameRenderer(formatter).to_csv(
  File "/usr/local/lib/python3.9/site-packages/pandas/util/_decorators.py", line 211, in wrapper
    return func(*args, **kwargs)
  File "/usr/local/lib/python3.9/site-packages/pandas/io/formats/format.py", line 1189, in to_csv
    csv_formatter.save()
  File "/usr/local/lib/python3.9/site-packages/pandas/io/formats/csvs.py", line 261, in save
    self._save()
  File "/usr/local/lib/python3.9/site-packages/pandas/io/formats/csvs.py", line 266, in _save
    self._save_body()
  File "/usr/local/lib/python3.9/site-packages/pandas/io/formats/csvs.py", line 304, in _save_body
    self._save_chunk(start_i, end_i)
  File "/usr/local/lib/python3.9/site-packages/pandas/io/formats/csvs.py", line 315, in _save_chunk
    libwriters.write_csv_rows(
  File "pandas/_libs/writers.pyx", line 55, in pandas._libs.writers.write_csv_rows
  File "/usr/local/lib/python3.9/site-packages/fsspec/spec.py", line 1616, in write
    self.flush()
  File "/usr/local/lib/python3.9/site-packages/fsspec/spec.py", line 1652, in flush
    self._initiate_upload()
  File "/usr/local/lib/python3.9/site-packages/gcsfs/core.py", line 1592, in _initiate_upload
    self.location = sync(
  File "/usr/local/lib/python3.9/site-packages/fsspec/asyn.py", line 100, in sync
    raise return_result
  File "/usr/local/lib/python3.9/site-packages/fsspec/asyn.py", line 55, in _runner
    result[0] = await coro
  File "/usr/local/lib/python3.9/site-packages/gcsfs/core.py", line 1708, in initiate_upload
    headers, _ = await fs._call(
  File "/usr/local/lib/python3.9/site-packages/gcsfs/core.py", line 418, in _call
    status, headers, info, contents = await self._request(
  File "/usr/local/lib/python3.9/site-packages/decorator.py", line 221, in fun
    return await caller(func, *(extras + args), **kw)
  File "/usr/local/lib/python3.9/site-packages/gcsfs/retry.py", line 149, in retry_request
    raise e
  File "/usr/local/lib/python3.9/site-packages/gcsfs/retry.py", line 114, in retry_request
    return await func(*args, **kwargs)
  File "/usr/local/lib/python3.9/site-packages/gcsfs/core.py", line 411, in _request
    validate_response(status, contents, path, args)
  File "/usr/local/lib/python3.9/site-packages/gcsfs/retry.py", line 101, in validate_response
    raise HttpError(error)
gcsfs.retry.HttpError: Anonymous caller does not have storage.objects.create access to the Google Cloud Storage object. Permission 'storage.objects.create' denied on resource (or it may not exist)., 401
[2023-03-27T03:17:04.176+0000] {taskinstance.py:1322} INFO - Marking task as FAILED. dag_id=projeto_agro, task_id=extract_data, execution_date=20230327T031638, start_date=20230327T031641, end_date=20230327T031704
[2023-03-27T03:17:04.192+0000] {standard_task_runner.py:100} ERROR - Failed to execute job 91 for task extract_data (Anonymous caller does not have storage.objects.create access to the Google Cloud Storage object. Permission 'storage.objects.create' denied on resource (or it may not exist)., 401; 235)
[2023-03-27T03:17:04.226+0000] {local_task_job.py:159} INFO - Task exited with return code 1
[2023-03-27T03:17:04.243+0000] {taskinstance.py:2582} INFO - 0 downstream tasks scheduled from follow-on schedule check
