[2023-03-28T00:38:41.589+0000] {taskinstance.py:1087} INFO - Dependencies all met for <TaskInstance: projeto_agro.transform_data manual__2023-03-28T00:37:30.242438+00:00 [queued]>
[2023-03-28T00:38:41.602+0000] {taskinstance.py:1087} INFO - Dependencies all met for <TaskInstance: projeto_agro.transform_data manual__2023-03-28T00:37:30.242438+00:00 [queued]>
[2023-03-28T00:38:41.602+0000] {taskinstance.py:1283} INFO - 
--------------------------------------------------------------------------------
[2023-03-28T00:38:41.602+0000] {taskinstance.py:1284} INFO - Starting attempt 1 of 1
[2023-03-28T00:38:41.602+0000] {taskinstance.py:1285} INFO - 
--------------------------------------------------------------------------------
[2023-03-28T00:38:41.620+0000] {taskinstance.py:1304} INFO - Executing <Task(PythonOperator): transform_data> on 2023-03-28 00:37:30.242438+00:00
[2023-03-28T00:38:41.627+0000] {standard_task_runner.py:55} INFO - Started process 1506 to run task
[2023-03-28T00:38:41.630+0000] {standard_task_runner.py:82} INFO - Running: ['airflow', 'tasks', 'run', 'projeto_agro', 'transform_data', 'manual__2023-03-28T00:37:30.242438+00:00', '--job-id', '160', '--raw', '--subdir', 'DAGS_FOLDER/main.py', '--cfg-path', '/tmp/tmp88stqj3_']
[2023-03-28T00:38:41.631+0000] {standard_task_runner.py:83} INFO - Job 160: Subtask transform_data
[2023-03-28T00:38:41.719+0000] {task_command.py:389} INFO - Running <TaskInstance: projeto_agro.transform_data manual__2023-03-28T00:37:30.242438+00:00 [running]> on host 48ec747c45e3
[2023-03-28T00:38:41.827+0000] {taskinstance.py:1511} INFO - Exporting the following env vars:
AIRFLOW_CTX_DAG_OWNER=airflow
AIRFLOW_CTX_DAG_ID=projeto_agro
AIRFLOW_CTX_TASK_ID=transform_data
AIRFLOW_CTX_EXECUTION_DATE=2023-03-28T00:37:30.242438+00:00
AIRFLOW_CTX_TRY_NUMBER=1
AIRFLOW_CTX_DAG_RUN_ID=manual__2023-03-28T00:37:30.242438+00:00
[2023-03-28T00:39:58.854+0000] {taskinstance.py:1772} ERROR - Task failed with exception
Traceback (most recent call last):
  File "/usr/local/lib/python3.9/site-packages/airflow/operators/python.py", line 175, in execute
    return_value = self.execute_callable()
  File "/usr/local/lib/python3.9/site-packages/airflow/operators/python.py", line 192, in execute_callable
    return self.python_callable(*self.op_args, **self.op_kwargs)
  File "/opt/airflow/dags/main.py", line 33, in transform
    transform.send_data_to_staging()
  File "/opt/airflow/dags/../../scripts/transform.py", line 106, in send_data_to_staging
    now = datetime.now()
NameError: name 'datetime' is not defined
[2023-03-28T00:39:59.033+0000] {taskinstance.py:1322} INFO - Marking task as FAILED. dag_id=projeto_agro, task_id=transform_data, execution_date=20230328T003730, start_date=20230328T003841, end_date=20230328T003959
[2023-03-28T00:39:59.168+0000] {standard_task_runner.py:100} ERROR - Failed to execute job 160 for task transform_data (name 'datetime' is not defined; 1506)
[2023-03-28T00:39:59.457+0000] {local_task_job.py:159} INFO - Task exited with return code 1
[2023-03-28T00:39:59.559+0000] {taskinstance.py:2582} INFO - 0 downstream tasks scheduled from follow-on schedule check
