[2023-03-27T14:38:54.030+0000] {taskinstance.py:1087} INFO - Dependencies all met for <TaskInstance: projeto_agro.extract_data manual__2023-03-27T14:38:48.883532+00:00 [queued]>
[2023-03-27T14:38:54.041+0000] {taskinstance.py:1087} INFO - Dependencies all met for <TaskInstance: projeto_agro.extract_data manual__2023-03-27T14:38:48.883532+00:00 [queued]>
[2023-03-27T14:38:54.041+0000] {taskinstance.py:1283} INFO - 
--------------------------------------------------------------------------------
[2023-03-27T14:38:54.041+0000] {taskinstance.py:1284} INFO - Starting attempt 1 of 1
[2023-03-27T14:38:54.041+0000] {taskinstance.py:1285} INFO - 
--------------------------------------------------------------------------------
[2023-03-27T14:38:54.054+0000] {taskinstance.py:1304} INFO - Executing <Task(PythonOperator): extract_data> on 2023-03-27 14:38:48.883532+00:00
[2023-03-27T14:38:54.059+0000] {standard_task_runner.py:55} INFO - Started process 333 to run task
[2023-03-27T14:38:54.062+0000] {standard_task_runner.py:82} INFO - Running: ['airflow', 'tasks', 'run', 'projeto_agro', 'extract_data', 'manual__2023-03-27T14:38:48.883532+00:00', '--job-id', '95', '--raw', '--subdir', 'DAGS_FOLDER/main.py', '--cfg-path', '/tmp/tmp7nce4l46']
[2023-03-27T14:38:54.063+0000] {standard_task_runner.py:83} INFO - Job 95: Subtask extract_data
[2023-03-27T14:38:54.134+0000] {task_command.py:389} INFO - Running <TaskInstance: projeto_agro.extract_data manual__2023-03-27T14:38:48.883532+00:00 [running]> on host de8151cd9b21
[2023-03-27T14:38:54.212+0000] {taskinstance.py:1511} INFO - Exporting the following env vars:
AIRFLOW_CTX_DAG_OWNER=airflow
AIRFLOW_CTX_DAG_ID=projeto_agro
AIRFLOW_CTX_TASK_ID=extract_data
AIRFLOW_CTX_EXECUTION_DATE=2023-03-27T14:38:48.883532+00:00
AIRFLOW_CTX_TRY_NUMBER=1
AIRFLOW_CTX_DAG_RUN_ID=manual__2023-03-27T14:38:48.883532+00:00
[2023-03-27T14:39:11.530+0000] {logging_mixin.py:137} WARNING - /opt/airflow/dags/../../scripts/extract.py:36 DtypeWarning: Columns (2) have mixed types. Specify dtype option on import or set low_memory=False.
[2023-03-27T14:39:48.280+0000] {retry.py:143} ERROR - _request out of retries on exception: ('invalid_scope: Invalid OAuth scope or ID token audience provided.', {'error': 'invalid_scope', 'error_description': 'Invalid OAuth scope or ID token audience provided.'})
Traceback (most recent call last):
  File "/usr/local/lib/python3.9/site-packages/gcsfs/retry.py", line 114, in retry_request
    return await func(*args, **kwargs)
  File "/usr/local/lib/python3.9/site-packages/gcsfs/core.py", line 401, in _request
    headers=self._get_headers(headers),
  File "/usr/local/lib/python3.9/site-packages/gcsfs/core.py", line 380, in _get_headers
    self.credentials.apply(out)
  File "/usr/local/lib/python3.9/site-packages/gcsfs/credentials.py", line 185, in apply
    self.maybe_refresh()
  File "/usr/local/lib/python3.9/site-packages/gcsfs/credentials.py", line 180, in maybe_refresh
    self.credentials.refresh(req)
  File "/usr/local/lib/python3.9/site-packages/google/oauth2/service_account.py", line 429, in refresh
    access_token, expiry, _ = _client.jwt_grant(
  File "/usr/local/lib/python3.9/site-packages/google/oauth2/_client.py", line 299, in jwt_grant
    response_data = _token_endpoint_request(
  File "/usr/local/lib/python3.9/site-packages/google/oauth2/_client.py", line 270, in _token_endpoint_request
    _handle_error_response(response_data, retryable_error)
  File "/usr/local/lib/python3.9/site-packages/google/oauth2/_client.py", line 69, in _handle_error_response
    raise exceptions.RefreshError(
google.auth.exceptions.RefreshError: ('invalid_scope: Invalid OAuth scope or ID token audience provided.', {'error': 'invalid_scope', 'error_description': 'Invalid OAuth scope or ID token audience provided.'})
[2023-03-27T14:39:48.290+0000] {taskinstance.py:1772} ERROR - Task failed with exception
Traceback (most recent call last):
  File "/usr/local/lib/python3.9/site-packages/airflow/operators/python.py", line 175, in execute
    return_value = self.execute_callable()
  File "/usr/local/lib/python3.9/site-packages/airflow/operators/python.py", line 192, in execute_callable
    return self.python_callable(*self.op_args, **self.op_kwargs)
  File "/opt/airflow/dags/main.py", line 16, in extract
    extract.save_data_raw()
  File "/opt/airflow/dags/../../scripts/extract.py", line 45, in save_data_raw
    self.all_data_faostat.to_csv('gs://data_raw_area_project_agro/' + path_file_faostat,storage_options={'token':self.credentials})
  File "/usr/local/lib/python3.9/site-packages/pandas/util/_decorators.py", line 211, in wrapper
    return func(*args, **kwargs)
  File "/usr/local/lib/python3.9/site-packages/pandas/core/generic.py", line 3720, in to_csv
    return DataFrameRenderer(formatter).to_csv(
  File "/usr/local/lib/python3.9/site-packages/pandas/util/_decorators.py", line 211, in wrapper
    return func(*args, **kwargs)
  File "/usr/local/lib/python3.9/site-packages/pandas/io/formats/format.py", line 1189, in to_csv
    csv_formatter.save()
  File "/usr/local/lib/python3.9/site-packages/pandas/io/formats/csvs.py", line 261, in save
    self._save()
  File "/usr/local/lib/python3.9/site-packages/pandas/io/formats/csvs.py", line 266, in _save
    self._save_body()
  File "/usr/local/lib/python3.9/site-packages/pandas/io/formats/csvs.py", line 304, in _save_body
    self._save_chunk(start_i, end_i)
  File "/usr/local/lib/python3.9/site-packages/pandas/io/formats/csvs.py", line 315, in _save_chunk
    libwriters.write_csv_rows(
  File "pandas/_libs/writers.pyx", line 55, in pandas._libs.writers.write_csv_rows
  File "/usr/local/lib/python3.9/site-packages/fsspec/spec.py", line 1616, in write
    self.flush()
  File "/usr/local/lib/python3.9/site-packages/fsspec/spec.py", line 1652, in flush
    self._initiate_upload()
  File "/usr/local/lib/python3.9/site-packages/gcsfs/core.py", line 1592, in _initiate_upload
    self.location = sync(
  File "/usr/local/lib/python3.9/site-packages/fsspec/asyn.py", line 100, in sync
    raise return_result
  File "/usr/local/lib/python3.9/site-packages/fsspec/asyn.py", line 55, in _runner
    result[0] = await coro
  File "/usr/local/lib/python3.9/site-packages/gcsfs/core.py", line 1708, in initiate_upload
    headers, _ = await fs._call(
  File "/usr/local/lib/python3.9/site-packages/gcsfs/core.py", line 418, in _call
    status, headers, info, contents = await self._request(
  File "/usr/local/lib/python3.9/site-packages/decorator.py", line 221, in fun
    return await caller(func, *(extras + args), **kw)
  File "/usr/local/lib/python3.9/site-packages/gcsfs/retry.py", line 144, in retry_request
    raise e
  File "/usr/local/lib/python3.9/site-packages/gcsfs/retry.py", line 114, in retry_request
    return await func(*args, **kwargs)
  File "/usr/local/lib/python3.9/site-packages/gcsfs/core.py", line 401, in _request
    headers=self._get_headers(headers),
  File "/usr/local/lib/python3.9/site-packages/gcsfs/core.py", line 380, in _get_headers
    self.credentials.apply(out)
  File "/usr/local/lib/python3.9/site-packages/gcsfs/credentials.py", line 185, in apply
    self.maybe_refresh()
  File "/usr/local/lib/python3.9/site-packages/gcsfs/credentials.py", line 180, in maybe_refresh
    self.credentials.refresh(req)
  File "/usr/local/lib/python3.9/site-packages/google/oauth2/service_account.py", line 429, in refresh
    access_token, expiry, _ = _client.jwt_grant(
  File "/usr/local/lib/python3.9/site-packages/google/oauth2/_client.py", line 299, in jwt_grant
    response_data = _token_endpoint_request(
  File "/usr/local/lib/python3.9/site-packages/google/oauth2/_client.py", line 270, in _token_endpoint_request
    _handle_error_response(response_data, retryable_error)
  File "/usr/local/lib/python3.9/site-packages/google/oauth2/_client.py", line 69, in _handle_error_response
    raise exceptions.RefreshError(
google.auth.exceptions.RefreshError: ('invalid_scope: Invalid OAuth scope or ID token audience provided.', {'error': 'invalid_scope', 'error_description': 'Invalid OAuth scope or ID token audience provided.'})
[2023-03-27T14:39:48.311+0000] {taskinstance.py:1322} INFO - Marking task as FAILED. dag_id=projeto_agro, task_id=extract_data, execution_date=20230327T143848, start_date=20230327T143854, end_date=20230327T143948
[2023-03-27T14:39:48.323+0000] {standard_task_runner.py:100} ERROR - Failed to execute job 95 for task extract_data (('invalid_scope: Invalid OAuth scope or ID token audience provided.', {'error': 'invalid_scope', 'error_description': 'Invalid OAuth scope or ID token audience provided.'}); 333)
[2023-03-27T14:39:48.364+0000] {local_task_job.py:159} INFO - Task exited with return code 1
[2023-03-27T14:39:48.384+0000] {taskinstance.py:2582} INFO - 0 downstream tasks scheduled from follow-on schedule check
