[2023-03-10T22:36:56.798+0000] {taskinstance.py:1083} INFO - Dependencies all met for <TaskInstance: projeto_agro.extract_data manual__2023-03-10T22:36:53.883225+00:00 [queued]>
[2023-03-10T22:36:56.808+0000] {taskinstance.py:1083} INFO - Dependencies all met for <TaskInstance: projeto_agro.extract_data manual__2023-03-10T22:36:53.883225+00:00 [queued]>
[2023-03-10T22:36:56.808+0000] {taskinstance.py:1279} INFO - 
--------------------------------------------------------------------------------
[2023-03-10T22:36:56.808+0000] {taskinstance.py:1280} INFO - Starting attempt 1 of 1
[2023-03-10T22:36:56.808+0000] {taskinstance.py:1281} INFO - 
--------------------------------------------------------------------------------
[2023-03-10T22:36:56.822+0000] {taskinstance.py:1300} INFO - Executing <Task(PythonOperator): extract_data> on 2023-03-10 22:36:53.883225+00:00
[2023-03-10T22:36:56.825+0000] {standard_task_runner.py:55} INFO - Started process 27 to run task
[2023-03-10T22:36:56.828+0000] {standard_task_runner.py:82} INFO - Running: ['airflow', 'tasks', 'run', 'projeto_agro', 'extract_data', 'manual__2023-03-10T22:36:53.883225+00:00', '--job-id', '65', '--raw', '--subdir', 'DAGS_FOLDER/main.py', '--cfg-path', '/tmp/tmpoayolq5m']
[2023-03-10T22:36:56.829+0000] {standard_task_runner.py:83} INFO - Job 65: Subtask extract_data
[2023-03-10T22:36:56.890+0000] {task_command.py:388} INFO - Running <TaskInstance: projeto_agro.extract_data manual__2023-03-10T22:36:53.883225+00:00 [running]> on host 1b87c3940542
[2023-03-10T22:36:56.956+0000] {taskinstance.py:1507} INFO - Exporting the following env vars:
AIRFLOW_CTX_DAG_OWNER=airflow
AIRFLOW_CTX_DAG_ID=projeto_agro
AIRFLOW_CTX_TASK_ID=extract_data
AIRFLOW_CTX_EXECUTION_DATE=2023-03-10T22:36:53.883225+00:00
AIRFLOW_CTX_TRY_NUMBER=1
AIRFLOW_CTX_DAG_RUN_ID=manual__2023-03-10T22:36:53.883225+00:00
[2023-03-10T22:36:58.335+0000] {taskinstance.py:1768} ERROR - Task failed with exception
Traceback (most recent call last):
  File "/usr/local/lib/python3.9/site-packages/airflow/operators/python.py", line 175, in execute
    return_value = self.execute_callable()
  File "/usr/local/lib/python3.9/site-packages/airflow/operators/python.py", line 192, in execute_callable
    return self.python_callable(*self.op_args, **self.op_kwargs)
  File "/opt/airflow/dags/main.py", line 15, in extract
    extract = Extract()
  File "/opt/airflow/dags/../../scripts/extract.py", line 9, in __init__
    self._get_faostat_data()
  File "/opt/airflow/dags/../../scripts/extract.py", line 15, in _get_faostat_data
    self.dataset_flags = pd.read_csv(zip_file.open('Production_Crops_Livestock_E_Flags.csv'))
NameError: name 'pd' is not defined
[2023-03-10T22:36:58.365+0000] {taskinstance.py:1318} INFO - Marking task as FAILED. dag_id=projeto_agro, task_id=extract_data, execution_date=20230310T223653, start_date=20230310T223656, end_date=20230310T223658
[2023-03-10T22:36:58.395+0000] {standard_task_runner.py:100} ERROR - Failed to execute job 65 for task extract_data (name 'pd' is not defined; 27)
[2023-03-10T22:36:58.443+0000] {local_task_job.py:208} INFO - Task exited with return code 1
[2023-03-10T22:36:58.486+0000] {taskinstance.py:2578} INFO - 0 downstream tasks scheduled from follow-on schedule check
